Workbook

Sheet DASHBOARD
A1: SELECT ACTIVE STRATEGIC SCENARIO: | B1: 2

Sheet README_Case_ContextCahaba Struc
A1: Cahaba Structural Engineering Simulation Brief
A2: Project Type: Professional Services Master Budget & Capacity Optimization Model
A3: Entity Structure: Sole Proprietorship / Principal-Led Engineering Firm
A4: Core Objective: Model cash flow lifecycle, optimize a hard billable-hour capacity bottleneck, and simulate a strategic scaling pivot.
A5: 1. The Operational Reality (The Inputs)
A6: Cahaba Structural Engineering is a highly profitable, specialized firm owned and operated by a single Principal Engineer ($PE$). The firm is currently facing a "good problem": demand for its services exceeds the physical hours the owner has available. The owner is considering hiring a Junior Engineer ($JE$) to scale operations but needs a dynamic financial model to test the viability of this fixed-overhead expansion.
A7: The Product Mix & Constraints
A8: The firm generates revenue through two core service lines:
A9: [Available Capacity: 160 Principal Hours / Month]
A10: │
A11: ├─► Service A: Complex Structural Consults (Requires PE Seal)
A12: │ Demand: Variable, High Margin
... A31: The firm’s monthly operating expenses do not behave linearly. They switch based on headcount:
A32: Expense Category | B32: Baseline (One-Man Show) | C32: Scaled Up (Hiring 1 Junior Engineer) | D32: Cost Behavior Type
A33: Principal Draw | B33: $12,000 / month | C33: $12,000 / month | D33: Fixed
A34: Office/Admin Overhead | B34: $2,500 / month | C34: $2,500 / month | D34: Fixed
A35: Engineering Software | B35: $300 / month (1 License) | C35: $600 / month (2 Licenses) | D35: Step-Fixed
A36: Junior Engineer Salary | B36: $0 / month | C36: $6,000 / month | D36: Step-Fixed
A37: Professional Liability Insurance | B37: $500 / baseline | C37: Base + 2% of gross billings | D37: Mixed (Semi-Variable)

Sheet INPUT_Control_Panel
A1: Service Name | B1: Comples Structural Consults | C1: Routine Civil Design | E1: Milestone Phase | F1: Collection Percentage | H1: Espense Category | I1: Monthly Baseline Cost
A2: Base Pricing | B2: 2500 | C2: 1600 | E2: Month 0: Upfront Retainer | F2: 0.3 | H2: Principle Draw | I2: 12000
A3: "Premium Fee" Adjustment Rate | B3: 1.2 | C3: 1 | E3: Month 1: Draft Submission | F3: 0.4 | H3: Office/Admin OH | I3: 2500
A4: PE Hours Required per project | B4: 10 | C4: 16 | E4: Month 2: Final Approval | F4: 0.3 | H4: Engineering Software (Per License) | I4: 300
A5: JE Hours Required per project | B5: 0 | C5: 14 | E5: Total Check | F5: =SUM(F2:F4) -> 1 | H5: Junior Engineer Base Salary | I5: 6000
H6: Professional Liability Base Rate | I6: 500

Sheet CALC_Revenue_Engine
A1: Project Lifecycle Timeline
B3: January | C3: February | D3: March | E3: April | F3: May | G3: June | H3: July | I3: August | J3: September | K3: October | L3: November | M3: December
A5: Service A: Standard Structural Projects Signed | B5: 4 | C5: 4 | D5: 5 | E5: 5 | F5: 6 | G5: 6
A6: Service A: Risk Premium Allocation Projects Signed | B6: 1 | C6: 1 | D6: 2 | E6: 2 | F6: 2 | G6: 3
A7: Service B: Routine Civil Projects Signed | B7: 3 | C7: 4 | D7: 4 | E7: 5 | F7: 5 | G7: 6
A8: Total Contracts Signed | B8: =SUM(B5:B7) -> 8 | C8: =SUM(C5:C7) -> 9 | D8: =SUM(D5:D7) -> 11 | E8: =SUM(E5:E7) -> 12 | F8: =SUM(F5:F7) -> 13 | G8: =SUM(G5:G7) -> 15 | H8: =SUM(H5:H7) -> 0 | I8: =SUM(I5:I7) -> 0 | ... M8: =SUM(M5:M7) -> 0
A10: CASH INFLOWS
A11: Upfront Retainers Collected (30% of Current Month Contracts) | B11: =((B5*INPUT_Control_Panel!$B$2)+(B6*INPUT_Control_Panel!$B$2*INPUT_Control_Panel!$B$3)+(B7*INPUT_Control_Panel!$C$2))*INPUT_Control_Panel!$F$2 -> 5340 | C11: =((C5*INPUT_Control_Panel!$B$2)+(C6*INPUT_Control_Panel!$B$2*INPUT_Control_Panel!$B$3)+(C7*INPUT_Control_Panel!$C$2))*INPUT_Control_Panel!$F$2 -> 5820 | D11: =((D5*INPUT_Control_Panel!$B$2)+(D6*INPUT_Control_Panel!$B$2*INPUT_Control_Panel!$B$3)+(D7*INPUT_Control_Panel!$C$2))*INPUT_Control_Panel!$F$2 -> 7470 | E11: =((E5*INPUT_Control_Panel!$B$2)+(E6*INPUT_Control_Panel!$B$2*INPUT_Control_Panel!$B$3)+(E7*INPUT_Control_Panel!$C$2))*INPUT_Control_Panel!$F$2 -> 7950 | F11: =((F5*INPUT_Control_Panel!$B$2)+(F6*INPUT_Control_Panel!$B$2*INPUT_Control_Panel!$B$3)+(F7*INPUT_Control_Panel!$C$2))*INPUT_Control_Panel!$F$2 -> 8700 | G11: =((G5*INPUT_Control_Panel!$B$2)+(G6*INPUT_Control_Panel!$B$2*INPUT_Control_Panel!$B$3)+(G7*INPUT_Control_Panel!$C$2))*INPUT_Control_Panel!$F$2 -> 10080 | H11: =((H5*INPUT_Control_Panel!$B$2)+(H6*INPUT_Control_Panel!$B$2*INPUT_Control_Panel!$B$3)+(H7*INPUT_Control_Panel!$C$2))*INPUT_Control_Panel!$F$2 -> 0 | I11: =((I5*INPUT_Control_Panel!$B$2)+(I6*INPUT_Control_Panel!$B$2*INPUT_Control_Panel!$B$3)+(I7*INPUT_Control_Panel!$C$2))*INPUT_Control_Panel!$F$2 -> 0 | ... M11: =((M5*INPUT_Control_Panel!$B$2)+(M6*INPUT_Control_Panel!$B$2*INPUT_Control_Panel!$B$3)+(M7*INPUT_Control_Panel!$C$2))*INPUT_Control_Panel!$F$2 -> 0
A12: Draft Submissions Collected (40% of Previous Month Contracts) | B12: =((B5*INPUT_Control_Panel!$B$2)+(B6*INPUT_Control_Panel!$B$2*INPUT_Control_Panel!$B$3)+(B7*INPUT_Control_Panel!$C$2))*INPUT_Control_Panel!$F$3 -> 7120 | C12: =((C5*INPUT_Control_Panel!$B$2)+(C6*INPUT_Control_Panel!$B$2*INPUT_Control_Panel!$B$3)+(C7*INPUT_Control_Panel!$C$2))*INPUT_Control_Panel!$F$3 -> 7760 | D12: =((D5*INPUT_Control_Panel!$B$2)+(D6*INPUT_Control_Panel!$B$2*INPUT_Control_Panel!$B$3)+(D7*INPUT_Control_Panel!$C$2))*INPUT_Control_Panel!$F$3 -> 9960 | E12: =((E5*INPUT_Control_Panel!$B$2)+(E6*INPUT_Control_Panel!$B$2*INPUT_Control_Panel!$B$3)+(E7*INPUT_Control_Panel!$C$2))*INPUT_Control_Panel!$F$3 -> 10600 | F12: =((F5*INPUT_Control_Panel!$B$2)+(F6*INPUT_Control_Panel!$B$2*INPUT_Control_Panel!$B$3)+(F7*INPUT_Control_Panel!$C$2))*INPUT_Control_Panel!$F$3 -> 11600 | G12: =((G5*INPUT_Control_Panel!$B$2)+(G6*INPUT_Control_Panel!$B$2*INPUT_Control_Panel!$B$3)+(G7*INPUT_Control_Panel!$C$2))*INPUT_Control_Panel!$F$3 -> 13440 | H12: =((H5*INPUT_Control_Panel!$B$2)+(H6*INPUT_Control_Panel!$B$2*INPUT_Control_Panel!$B$3)+(H7*INPUT_Control_Panel!$C$2))*INPUT_Control_Panel!$F$3 -> 0 | I12: =((I5*INPUT_Control_Panel!$B$2)+(I6*INPUT_Control_Panel!$B$2*INPUT_Control_Panel!$B$3)+(I7*INPUT_Control_Panel!$C$2))*INPUT_Control_Panel!$F$3 -> 0 | ... M12: =((M5*INPUT_Control_Panel!$B$2)+(M6*INPUT_Control_Panel!$B$2*INPUT_Control_Panel!$B$3)+(M7*INPUT_Control_Panel!$C$2))*INPUT_Control_Panel!$F$3 -> 0
A13: Final Approvals Collected (30% of Two Months Ago Contracts) | B13: =((B5*INPUT_Control_Panel!$B$2)+(B6*INPUT_Control_Panel!$B$2*INPUT_Control_Panel!$B$3)+(B7*INPUT_Control_Panel!$C$2))*INPUT_Control_Panel!$F$4 -> 5340 | C13: =((C5*INPUT_Control_Panel!$B$2)+(C6*INPUT_Control_Panel!$B$2*INPUT_Control_Panel!$B$3)+(C7*INPUT_Control_Panel!$C$2))*INPUT_Control_Panel!$F$4 -> 5820 | D13: =((D5*INPUT_Control_Panel!$B$2)+(D6*INPUT_Control_Panel!$B$2*INPUT_Control_Panel!$B$3)+(D7*INPUT_Control_Panel!$C$2))*INPUT_Control_Panel!$F$4 -> 7470 | E13: =((E5*INPUT_Control_Panel!$B$2)+(E6*INPUT_Control_Panel!$B$2*INPUT_Control_Panel!$B$3)+(E7*INPUT_Control_Panel!$C$2))*INPUT_Control_Panel!$F$4 -> 7950 | F13: =((F5*INPUT_Control_Panel!$B$2)+(F6*INPUT_Control_Panel!$B$2*INPUT_Control_Panel!$B$3)+(F7*INPUT_Control_Panel!$C$2))*INPUT_Control_Panel!$F$4 -> 8700 | G13: =((G5*INPUT_Control_Panel!$B$2)+(G6*INPUT_Control_Panel!$B$2*INPUT_Control_Panel!$B$3)+(G7*INPUT_Control_Panel!$C$2))*INPUT_Control_Panel!$F$4 -> 10080 | H13: =((H5*INPUT_Control_Panel!$B$2)+(H6*INPUT_Control_Panel!$B$2*INPUT_Control_Panel!$B$3)+(H7*INPUT_Control_Panel!$C$2))*INPUT_Control_Panel!$F$4 -> 0 | I13: =((I5*INPUT_Control_Panel!$B$2)+(I6*INPUT_Control_Panel!$B$2*INPUT_Control_Panel!$B$3)+(I7*INPUT_Control_Panel!$C$2))*INPUT_Control_Panel!$F$4 -> 0 | ... M13: =((M5*INPUT_Control_Panel!$B$2)+(M6*INPUT_Control_Panel!$B$2*INPUT_Control_Panel!$B$3)+(M7*INPUT_Control_Panel!$C$2))*INPUT_Control_Panel!$F$4 -> 0
A14: Total Monthly Cash Inflows | B14: =SUM(B11:B13) -> 17800 | C14: =SUM(C11:C13) -> 19400 | D14: =SUM(D11:D13) -> 24900 | E14: =SUM(E11:E13) -> 26500 | F14: =SUM(F11:F13) -> 29000 | G14: =SUM(G11:G13) -> 33600 | H14: =SUM(H11:H13) -> 0 | I14: =SUM(I11:I13) -> 0 | ... M14: =SUM(M11:M13) -> 0
A16: LABOR CAPACITY TRACKING (ONE-MAN SHOW)
A17: Principal Hours Consumed: Standard Structural | B17: =B5 * INPUT_Control_Panel!$B$4 -> 40 | C17: =C5 * INPUT_Control_Panel!$B$4 -> 40 | D17: =D5 * INPUT_Control_Panel!$B$4 -> 50 | E17: =E5 * INPUT_Control_Panel!$B$4 -> 50 | F17: =F5 * INPUT_Control_Panel!$B$4 -> 60 | G17: =G5 * INPUT_Control_Panel!$B$4 -> 60 | H17: =H5 * INPUT_Control_Panel!$B$4 -> 0 | I17: =I5 * INPUT_Control_Panel!$B$4 -> 0 | ... M17: =M5 * INPUT_Control_Panel!$B$4 -> 0
A18: Principal Hours Consumed: Risk Premium | B18: =B6 * INPUT_Control_Panel!$B$4 -> 10 | C18: =C6 * INPUT_Control_Panel!$B$4 -> 10 | D18: =D6 * INPUT_Control_Panel!$B$4 -> 20 | E18: =E6 * INPUT_Control_Panel!$B$4 -> 20 | F18: =F6 * INPUT_Control_Panel!$B$4 -> 20 | G18: =G6 * INPUT_Control_Panel!$B$4 -> 30 | H18: =H6 * INPUT_Control_Panel!$B$4 -> 0 | I18: =I6 * INPUT_Control_Panel!$B$4 -> 0 | ... M18: =M6 * INPUT_Control_Panel!$B$4 -> 0
A19: Principal Hours Consumed: Routine Civil | B19: =B7 * INPUT_Control_Panel!$C$4 -> 48 | C19: =C7 * INPUT_Control_Panel!$C$4 -> 64 | D19: =D7 * INPUT_Control_Panel!$C$4 -> 64 | E19: =E7 * INPUT_Control_Panel!$C$4 -> 80 | F19: =F7 * INPUT_Control_Panel!$C$4 -> 80 | G19: =G7 * INPUT_Control_Panel!$C$4 -> 96 | H19: =H7 * INPUT_Control_Panel!$C$4 -> 0 | I19: =I7 * INPUT_Control_Panel!$C$4 -> 0 | ... M19: =M7 * INPUT_Control_Panel!$C$4 -> 0
A20: Total Principal Hours Required | B20: =SUM(B17:B19) -> 98 | C20: =SUM(C17:C19) -> 114 | D20: =SUM(D17:D19) -> 134 | E20: =SUM(E17:E19) -> 150 | F20: =SUM(F17:F19) -> 160 | G20: =SUM(G17:G19) -> 186 | H20: =SUM(H17:H19) -> 0 | I20: =SUM(I17:I19) -> 0 | ... M20: =SUM(M17:M19) -> 0
A21: Maximum Available Principal Hours | B21: 160 | C21: =B21 -> 160 | D21: =C21 -> 160 | E21: =D21 -> 160 | F21: =E21 -> 160 | G21: =F21 -> 160 | H21: =G21 -> 160 | I21: =H21 -> 160 | J21: =I21 -> 160 | ... M21: =L21 -> 160
A22: Capacity Shortage / (Surplus Hours) | B22: =B20 - B21 -> -62 | C22: =C20 - C21 -> -46 | D22: =D20 - D21 -> -26 | E22: =E20 - E21 -> -10 | F22: =F20 - F21 -> 0 | G22: =G20 - G21 -> 26 | H22: =H20 - H21 -> -160 | I22: =I20 - I21 -> -160 | ... M22: =M20 - M21 -> -160
A25: STRATEGIC DECISION LAYER
A26: Active Strategy (1 = Baseline, 2 = Premium Pricing Optimization, 3 = Staff Expansion) | B26: =DASHBOARD!$B$1 -> 2
A28: Dynamic Vol: Standard Structural | B28: =IF($B$26=1, B5, IF($B$26=2, ROUND(B5*0.8, 0), B5)) -> 3 | C28: =IF($B$26=1, C5, IF($B$26=2, ROUND(C5*0.8, 0), C5)) -> 3 | D28: =IF($B$26=1, D5, IF($B$26=2, ROUND(D5*0.8, 0), D5)) -> 4 | E28: =IF($B$26=1, E5, IF($B$26=2, ROUND(E5*0.8, 0), E5)) -> 4 | F28: =IF($B$26=1, F5, IF($B$26=2, ROUND(F5*0.8, 0), F5)) -> 5 | G28: =IF($B$26=1, G5, IF($B$26=2, ROUND(G5*0.8, 0), G5)) -> 5 | H28: =IF($B$26=1, H5, IF($B$26=2, ROUND(H5*0.8, 0), H5)) -> 0 | I28: =IF($B$26=1, I5, IF($B$26=2, ROUND(I5*0.8, 0), I5)) -> 0 | ... M28: =IF($B$26=1, M5, IF($B$26=2, ROUND(M5*0.8, 0), M5)) -> 0
A29: Dynamic Vol: Risk Premium Structural | B29: =IF($B$26=1, B6, IF($B$26=2, B6 + ROUND(B5*0.2, 0), B6)) -> 2 | C29: =IF($B$26=1, C6, IF($B$26=2, C6 + ROUND(C5*0.2, 0), C6)) -> 2 | D29: =IF($B$26=1, D6, IF($B$26=2, D6 + ROUND(D5*0.2, 0), D6)) -> 3 | E29: =IF($B$26=1, E6, IF($B$26=2, E6 + ROUND(E5*0.2, 0), E6)) -> 3 | F29: =IF($B$26=1, F6, IF($B$26=2, F6 + ROUND(F5*0.2, 0), F6)) -> 3 | G29: =IF($B$26=1, G6, IF($B$26=2, G6 + ROUND(G5*0.2, 0), G6)) -> 4 | H29: =IF($B$26=1, H6, IF($B$26=2, H6 + ROUND(H5*0.2, 0), H6)) -> 0 | I29: =IF($B$26=1, I6, IF($B$26=2, I6 + ROUND(I5*0.2, 0), I6)) -> 0 | ... M29: =IF($B$26=1, M6, IF($B$26=2, M6 + ROUND(M5*0.2, 0), M6)) -> 0
A30: Dynamic Vol: Routine Civil | B30: =B7 -> 3 | C30: =C7 -> 4 | D30: =D7 -> 4 | E30: =E7 -> 5 | F30: =F7 -> 5 | G30: =G7 -> 6
A32: DYNAMIC LABOR TRACKING
A33: Dynamic Principal Hours Consumed | B33: =IF($B$26=3, (B28*10)+(B29*10)+(B30*2), (B28*10)+(B29*10)+(B30*16)) -> 98 | C33: =IF($B$26=3, (C28*10)+(C29*10)+(C30*2), (C28*10)+(C29*10)+(C30*16)) -> 114 | D33: =IF($B$26=3, (D28*10)+(D29*10)+(D30*2), (D28*10)+(D29*10)+(D30*16)) -> 134 | E33: =IF($B$26=3, (E28*10)+(E29*10)+(E30*2), (E28*10)+(E29*10)+(E30*16)) -> 150 | F33: =IF($B$26=3, (F28*10)+(F29*10)+(F30*2), (F28*10)+(F29*10)+(F30*16)) -> 160 | G33: =IF($B$26=3, (G28*10)+(G29*10)+(G30*2), (G28*10)+(G29*10)+(G30*16)) -> 186 | H33: =IF($B$26=3, (H28*10)+(H29*10)+(H30*2), (H28*10)+(H29*10)+(H30*16)) -> 0 | I33: =IF($B$26=3, (I28*10)+(I29*10)+(I30*2), (I28*10)+(I29*10)+(I30*16)) -> 0 | ... M33: =IF($B$26=3, (M28*10)+(M29*10)+(M30*2), (M28*10)+(M29*10)+(M30*16)) -> 0
A34: Dynamic Junior Hours Consumed | B34: =IF($B$26=3, B30*14, 0) -> 0 | C34: =IF($B$26=3, C30*14, 0) -> 0 | D34: =IF($B$26=3, D30*14, 0) -> 0 | E34: =IF($B$26=3, E30*14, 0) -> 0 | F34: =IF($B$26=3, F30*14, 0) -> 0 | G34: =IF($B$26=3, G30*14, 0) -> 0 | H34: =IF($B$26=3, H30*14, 0) -> 0 | I34: =IF($B$26=3, I30*14, 0) -> 0 | ... M34: =IF($B$26=3, M30*14, 0) -> 0
A35: Principal Hours Shortage / (Surplus) | B35: =B33 - 160 -> -62 | C35: =C33 - 160 -> -46 | D35: =D33 - 160 -> -26 | E35: =E33 - 160 -> -10 | F35: =F33 - 160 -> 0 | G35: =G33 - 160 -> 26 | H35: =H33 - 160 -> -160 | I35: =I33 - 160 -> -160 | ... M35: =M33 - 160 -> -160
A37: DYNAMIC PROFIT & LOSS ANALYSIS
A38: Dynamic Gross Revenue | B38: =(B28*INPUT_Control_Panel!$B$2)+(B29*INPUT_Control_Panel!$B$2*INPUT_Control_Panel!$B$3)+(B30*INPUT_Control_Panel!$C$2) -> 18300 | C38: =(C28*INPUT_Control_Panel!$B$2)+(C29*INPUT_Control_Panel!$B$2*INPUT_Control_Panel!$B$3)+(C30*INPUT_Control_Panel!$C$2) -> 19900 | D38: =(D28*INPUT_Control_Panel!$B$2)+(D29*INPUT_Control_Panel!$B$2*INPUT_Control_Panel!$B$3)+(D30*INPUT_Control_Panel!$C$2) -> 25400 | E38: =(E28*INPUT_Control_Panel!$B$2)+(E29*INPUT_Control_Panel!$B$2*INPUT_Control_Panel!$B$3)+(E30*INPUT_Control_Panel!$C$2) -> 27000 | F38: =(F28*INPUT_Control_Panel!$B$2)+(F29*INPUT_Control_Panel!$B$2*INPUT_Control_Panel!$B$3)+(F30*INPUT_Control_Panel!$C$2) -> 29500 | G38: =(G28*INPUT_Control_Panel!$B$2)+(G29*INPUT_Control_Panel!$B$2*INPUT_Control_Panel!$B$3)+(G30*INPUT_Control_Panel!$C$2) -> 34100 | H38: =(H28*INPUT_Control_Panel!$B$2)+(H29*INPUT_Control_Panel!$B$2*INPUT_Control_Panel!$B$3)+(H30*INPUT_Control_Panel!$C$2) -> 0 | I38: =(I28*INPUT_Control_Panel!$B$2)+(I29*INPUT_Control_Panel!$B$2*INPUT_Control_Panel!$B$3)+(I30*INPUT_Control_Panel!$C$2) -> 0 | ... M38: =(M28*INPUT_Control_Panel!$B$2)+(M29*INPUT_Control_Panel!$B$2*INPUT_Control_Panel!$B$3)+(M30*INPUT_Control_Panel!$C$2) -> 0
A39: Less: Operating Expenses
A40: Principal Draw | B40: =INPUT_Control_Panel!$I$2 -> 12000 | C40: =INPUT_Control_Panel!$I$2 -> 12000 | D40: =INPUT_Control_Panel!$I$2 -> 12000 | E40: =INPUT_Control_Panel!$I$2 -> 12000 | F40: =INPUT_Control_Panel!$I$2 -> 12000 | G40: =INPUT_Control_Panel!$I$2 -> 12000 | H40: =INPUT_Control_Panel!$I$2 -> 12000 | I40: =INPUT_Control_Panel!$I$2 -> 12000 | ... M40: =INPUT_Control_Panel!$I$2 -> 12000
A41: Office/Admind OH | B41: =INPUT_Control_Panel!$I$3 -> 2500 | C41: =INPUT_Control_Panel!$I$3 -> 2500 | D41: =INPUT_Control_Panel!$I$3 -> 2500 | E41: =INPUT_Control_Panel!$I$3 -> 2500 | F41: =INPUT_Control_Panel!$I$3 -> 2500 | G41: =INPUT_Control_Panel!$I$3 -> 2500 | H41: =INPUT_Control_Panel!$I$3 -> 2500 | I41: =INPUT_Control_Panel!$I$3 -> 2500 | ... M41: =INPUT_Control_Panel!$I$3 -> 2500
A42: Engineering Software Licenses | B42: =IF($B$26=3, INPUT_Control_Panel!$I$4*2, INPUT_Control_Panel!$I$4) -> 300 | C42: =IF($B$26=3, INPUT_Control_Panel!$I$4*2, INPUT_Control_Panel!$I$4) -> 300 | D42: =IF($B$26=3, INPUT_Control_Panel!$I$4*2, INPUT_Control_Panel!$I$4) -> 300 | E42: =IF($B$26=3, INPUT_Control_Panel!$I$4*2, INPUT_Control_Panel!$I$4) -> 300 | F42: =IF($B$26=3, INPUT_Control_Panel!$I$4*2, INPUT_Control_Panel!$I$4) -> 300 | G42: =IF($B$26=3, INPUT_Control_Panel!$I$4*2, INPUT_Control_Panel!$I$4) -> 300 | H42: =IF($B$26=3, INPUT_Control_Panel!$I$4*2, INPUT_Control_Panel!$I$4) -> 300 | I42: =IF($B$26=3, INPUT_Control_Panel!$I$4*2, INPUT_Control_Panel!$I$4) -> 300 | ... M42: =IF($B$26=3, INPUT_Control_Panel!$I$4*2, INPUT_Control_Panel!$I$4) -> 300
A43: Junior Engineer Salary | B43: =IF($B$26=3, INPUT_Control_Panel!$I$5, 0) -> 0 | C43: =IF($B$26=3, INPUT_Control_Panel!$I$5, 0) -> 0 | D43: =IF($B$26=3, INPUT_Control_Panel!$I$5, 0) -> 0 | E43: =IF($B$26=3, INPUT_Control_Panel!$I$5, 0) -> 0 | F43: =IF($B$26=3, INPUT_Control_Panel!$I$5, 0) -> 0 | G43: =IF($B$26=3, INPUT_Control_Panel!$I$5, 0) -> 0 | H43: =IF($B$26=3, INPUT_Control_Panel!$I$5, 0) -> 0 | I43: =IF($B$26=3, INPUT_Control_Panel!$I$5, 0) -> 0 | ... M43: =IF($B$26=3, INPUT_Control_Panel!$I$5, 0) -> 0
A44: Professional Liability Insurance | B44: =INPUT_Control_Panel!$I$6 + (B38 * 0.02) -> 866 | C44: =INPUT_Control_Panel!$I$6 + (C38 * 0.02) -> 898 | D44: =INPUT_Control_Panel!$I$6 + (D38 * 0.02) -> 1008 | E44: =INPUT_Control_Panel!$I$6 + (E38 * 0.02) -> 1040 | F44: =INPUT_Control_Panel!$I$6 + (F38 * 0.02) -> 1090 | G44: =INPUT_Control_Panel!$I$6 + (G38 * 0.02) -> 1182 | H44: =INPUT_Control_Panel!$I$6 + (H38 * 0.02) -> 500 | I44: =INPUT_Control_Panel!$I$6 + (I38 * 0.02) -> 500 | ... M44: =INPUT_Control_Panel!$I$6 + (M38 * 0.02) -> 500
A45: Total Operating Expenses | B45: =SUM(B40:B44) -> 15666 | C45: =SUM(C40:C44) -> 15698 | D45: =SUM(D40:D44) -> 15808 | E45: =SUM(E40:E44) -> 15840 | F45: =SUM(F40:F44) -> 15890 | G45: =SUM(G40:G44) -> 15982 | H45: =SUM(H40:H44) -> 15300 | I45: =SUM(I40:I44) -> 15300 | ... M45: =SUM(M40:M44) -> 15300
A46: Dynamic Net Income | B46: =B38-B45 -> 2634 | C46: =C38-C45 -> 4202 | D46: =D38-D45 -> 9592 | E46: =E38-E45 -> 11160 | F46: =F38-F45 -> 13610 | G46: =G38-G45 -> 18118 | H46: =H38-H45 -> -15300 | I46: =I38-I45 -> -15300 | ... M46: =M38-M45 -> -15300
A50: Strategy Option | B50: June Principal Hours Required | C50: Standard Monthly Capacity Cap
A51: Strategy 1: Status Quo | B51: =G20 -> 186 | C51: 160
A52: Strategy 2: Premium Pricing | B52: =(IF(2=2, ROUND(G5*0.8, 0), G5)*10)+(IF(2=2, G6 + ROUND(G5*0.2, 0), G6)*10)+(G7*16) -> 186 | C52: 160
...
